Workbook
Name Aa: '[1]ESPECTRO DE DISEÑO'!$C$7
Name Almacenamiento: TABLAS!$J$38:$J$39
Name Av: '[1]ESPECTRO DE DISEÑO'!$C$8
Name Crítico: #REF!
Name critico2: #REF!
Name Datos: #REF!
Name Educativos: TABLAS!$J$31:$J$34
Name Fa: TABLAS!#REF!
Name Fv: TABLAS!#REF!
Name Garajes: TABLAS!$J$40:$J$41
Name hp: 'ESPECTRO NSR-10'!$C$29
Name K: '[2]ESPECTRO DE DISEÑO'!$B$29
Name map: [2]MASA!$H$22
Name mt: [2]MASA!$H$26
Name MUNICIPIOS: TABLAS!$A$2:$A$1124
Name np: 'ESPECTRO NSR-10'!$C$31
Name Npisos: '[2]ESPECTRO DE DISEÑO'!$B$21
Name Oficinas: TABLAS!$J$28:$J$30
Name pConcreto: [2]EDIFICIO!$G$16
Name Residencial: TABLAS!$J$35:$J$37
Name Reuniones: TABLAS!$J$23:$J$27
Name Sa: '[2]ESPECTRO DE DISEÑO'!$B$28
Name SISTEMAS: TABLAS!$N$2:$N$5
Name SISTEMAS: [3]TABLAS!$M$2:$M$5
Name SUELO: TABLAS!#REF!
Name Ta: '[1]ESPECTRO DE DISEÑO'!$C$25
Name TipoSuelo: '[1]ESPECTRO DE DISEÑO'!$C$10
Name USO: TABLAS!#REF!
Name vS: [2]FHE!$C$12

Sheet TABLAS
A1: Municipio | B1: Código municipio | C1: ACELERACIÓN PICO EFECTIVA (Aa) | D1: VELOCIDAD PICO EFECTIVA (Av) | E1: Amenaza sísmica | F1: Ae | G1: Ad | N1: Sistema estructural | O1: Ct | P1: α
A2: Abejorral | B2: 5002 | C2: 0.15 | D2: 0.2 | E2: Alta | F2: 0.13 | G2: 0.07 | J2: CARGAS MUERTAS MUROS | N2: 1. Pórticos de concreto reforzado resistente a momentos | O2: 0.047 | P2: 0.9 | S2: Tablas de valores para el cálculo del espectro Fa
A3: Abrego | B3: 54003 | C3: 0.25 | D3: 0.2 | E3: Alta | F3: 0.07 | G3: 0.04 | N3: 2. Pórticos de acero estructural resistente a momentos | O3: 0.072 | P3: 0.8 | S3: Suelo\Aa | T3: 0.05 | U3: 0.1 | V3: 0.15 | W3: 0.2 | X3: 0.25 | Y3: 0.3 | Z3: 0.35 | AA3: 0.4 | AB3: 0.45 | AC3: 0.5
A4: Abriaquí | B4: 5004 | C4: 0.2 | D4: 0.25 | E4: Alta | F4: 0.13 | G4: 0.07 | J4: MUROS NO ESTRUCTURALES tabla B.3.4.2-4 | K4: Carga muertas (kN/m2) | N4: 3. Pórticos arriostrados de acero estructural | O4: 0.073 | P4: 0.75 | S4: A | T4: 0.8 | U4: 0.8 | V4: 0.8 | W4: 0.8 | X4: 0.8 | Y4: 0.8 | Z4: 0.8 | AA4: 0.8 | AB4: 0.8 | AC4: 0.8
A5: Acacias | B5: 50006 | C5: 0.3 | D5: 0.3 | E5: Alta | F5: 0.17 | G5: 0.06 | J5: Mamposteria de arcilla e = 0.10m | K5: 1.8 | N5: 4. Sistema estructural basado en muros de rigidez | O5: 0.049 | P5: 0.75 | S5: B | T5: 1 | U5: 1 | V5: 1 | W5: 1 | X5: 1 | Y5: 1 | Z5: 1 | AA5: 1 | AB5: 1 | AC5: 1
A6: Acandí | B6: 27006 | C6: 0.25 | D6: 0.25 | E6: Alta | F6: 0.09 | G6: 0.04 | J6: Mamposteria de arcilla e = 0.15m | K6: 2.5 | N6: 5. Combinado de porticos y muros de concreto reforzado | O6: =+AVERAGE(O2,O5) -> 0.048 | P6: =+AVERAGE(P2,P5) -> 0.825 | S6: C | T6: 1.2 | U6: 1.2 | V6: 1.2 | W6: 1.2 | X6: 1.15 | Y6: 1.1 | Z6: 1.05 | AA6: 1 | AB6: 1 | AC6: 1
A7: Acevedo | B7: 41006 | C7: 0.3 | D7: 0.15 | E7: Alta | F7: 0.17 | G7: 0.06 | J7: Mamposteria de arcilla e = 0.20m | K7: 3.1 | S7: D | T7: 1.6 | U7: 1.6 | V7: 1.5 | W7: 1.4 | X7: 1.3 | Y7: 1.2 | Z7: 1.15 | AA7: 1.1 | AB7: 1 | AC7: 0.9
A8: Achí | B8: 13006 | C8: 0.15 | D8: 0.15 | E8: Intermedia | F8: 0.07 | G8: 0.04 | J8: Mamposteria de arcilla e = 0.25m | K8: 3.8 | N8: Sistema estructural (tablas A.3-1:3 de la NSR-10) | O8: Ro | P8: Ωo | S8: E | T8: 2.5 | U8: 2.5 | V8: =+W8+(U8-W8)/2 -> 2.1 | W8: 1.7 | X8: =+Y8+(W8-Y8)/2 -> 1.45 | Y8: 1.2 | Z8: =+AA8+(Y8-AA8)/2 -> 1.05 | AA8: 0.9 | AB8: 0.9 | AC8: 0.9
A9: Agrado | B9: 41013 | C9: 0.3 | D9: 0.15 | E9: Alta | F9: 0.26 | G9: 0.08 | J9: Mamposteria de arcilla e = 0.30m | K9: 4.4 | N9: Muros estructurales de concreto (DES) | O9: 5 | P9: 2.5 | S9: F
A10: Agua de Dios | B10: 25001 | C10: 0.2 | D10: 0.2 | E10: Intermedia | F10: 0.11 | G10: 0.06 | N10: Muros de mamposteria reforzada de bloque perf. Vert. (DES) | O10: 3.5 | P10: 2.5 | S10: F1
A11: Aguachica | B11: 20011 | C11: 0.15 | D11: 0.15 | E11: Intermedia | F11: 0.08 | G11: 0.04 | N11: Muros de mamposteria reforzada de bloque perf. Vert. (DMO) | O11: 2.5 | P11: 2.5 | S11: F2
A12: Aguada | B12: 68013 | C12: 0.15 | D12: 0.2 | E12: Intermedia | F12: 0.17 | G12: 0.09 | J12: MUROS NO ESTRUCTURALES tabla B.3.4.2-4 | K12: Carga muertas (kN/m2) | N12: Muros de mamposteria parcialmente reforzada de bloque perf. Vert. | O12: 2 | P12: 2.5 | S12: F3
A13: Aguadas | B13: 17013 | C13: 0.25 | D13: 0.25 | E13: Alta | F13: 0.2 | G13: 0.1 | J13: Mamposteria de concreto e = 0.10m | K13: =24*0.1 -> 2.4 | N13: Porticos resistentes a momentos de concreto (DES) | O13: 7 | P13: 3 | S13: F4
A14: Aguazul | B14: 85010 | C14: 0.3 | D14: 0.2 | E14: Alta | F14: 0.14 | G14: 0.06 | J14: Mamposteria de concreto e = 0.12m | K14: =24*0.12 -> 2.88 | N14: Porticos resistentes a momentos de concreto (DMO) | O14: 5 | P14: 3 | S14: Tablas de valores para el cálculo del espectro Fv
A15: Agustín Codazzi | B15: 20013 | C15: 0.1 | D15: 0.1 | E15: Baja | F15: 0.07 | G15: 0.04 | J15: Mamposteria de concreto e = 0.15m | K15: =24*0.15 -> 3.6 | N15: Porticos resistentes a momentos de acero (DES) | O15: 7 | P15: 3 | S15: Suelo\Av | T15: 0.05 | U15: 0.1 | V15: 0.15 | W15: 0.2 | X15: 0.25 | Y15: 0.3 | Z15: 0.35 | AA15: 0.4 | AB15: 0.45 | AC15: 0.5
A16: Aipe | B16: 41016 | C16: 0.25 | D16: 0.25 | E16: Alta | F16: 0.14 | G16: 0.05 | J16: Mamposteria de concreto e = 0.16m | K16: =24*0.16 -> 3.84 | N16: Porticos resistentes a momentos de acero perfiles de lamina y PTE (DMI) | O16: 1.5 | P16: 1.5 | S16: A | T16: 0.8 | U16: 0.8 | V16: 0.8 | W16: 0.8 | X16: 0.8 | Y16: 0.8 | Z16: 0.8 | AA16: 0.8 | AB16: 0.8 | AC16: 0.8
A17: Albán | B17: 52019 | C17: 0.25 | D17: 0.25 | E17: Alta | F17: 0.16 | G17: 0.08 | J17: Mamposteria de concreto e = 0.20m | K17: =24*0.2 -> 4.8 | N17: Estructura de pendulo invertido de porticos de acero resistente momt. (DES) | O17: 2.5 | P17: 2 | S17: B | T17: 1 | U17: 1 | V17: 1 | W17: 1 | X17: 1 | Y17: 1 | Z17: 1 | AA17: 1 | AB17: 1 | AC17: 1
A18: Albán | B18: 25019 | C18: 0.15 | D18: 0.2 | E18: Intermedia | F18: 0.16 | G18: 0.06 | J18: Mamposteria de concreto e = 0.25m | K18: =24*0.25 -> 6 | S18: C | T18: 1.7 | U18: 1.7 | V18: 1.65 | W18: 1.6 | X18: 1.55 | Y18: 1.5 | Z18: 1.45 | AA18: 1.4 | AB18: 1.35 | AC18: 1.3
A19: Albania | B19: 44035 | C19: 0.1 | D19: 0.1 | E19: Baja | F19: 0.08 | G19: 0.04 | J19: Mamposteria de concreto e = 0.30m | K19: =24*0.3 -> 7.2 | S19: D | T19: 2.4 | U19: 2.4 | V19: 2.2 | W19: 2 | X19: 1.9 | Y19: 1.8 | Z19: 1.7 | AA19: 1.6 | AB19: 1.55 | AC19: 1.5
A20: Albania | B20: 18029 | C20: 0.15 | D20: 0.15 | E20: Intermedia | F20: 0.06 | G20: 0.04 | S20: E | T20: 3.5 | U20: 3.5 | V20: =+W20+(U20-W20)/2 -> 3.35 | W20: 3.2 | X20: =+Y20+(W20-Y20)/2 -> 3 | Y20: 2.8 | Z20: =+AA20+(Y20-AA20)/2 -> 2.6 | AA20: 2.4 | AB20: =+AC20+(AA20-AC20)/2 -> 2.4 | AC20: 2.4
A21: Albania | B21: 68020 | C21: 0.15 | D21: 0.15 | E21: Intermedia | F21: 0.09 | G21: 0.06 | I21: CARGAS VIVAS | S21: F
A22: Alcalá | B22: 76020 | C22: 0.25 | D22: 0.25 | E22: Alta | F22: 0.16 | G22: 0.1 | I22: Categoria | J22: Tipo de ocupacion | K22: Carga kN/m2 | S22: F1
A23: Aldana | B23: 52022 | C23: 0.25 | D23: 0.25 | E23: Alta | F23: 0.14 | G23: 0.08 | I23: Reuniones | J23: Balcones | K23: 5 | S23: F2
A24: Alejandría | B24: 5021 | C24: 0.15 | D24: 0.2 | E24: Intermedia | F24: 0.09 | G24: 0.05 | I24: Reuniones | J24: Corredores y escaleras | K24: 5 | S24: F3
A25: Algarrobo | B25: 47030 | C25: 0.1 | D25: 0.1 | E25: Baja | F25: 0.05 | G25: 0.02 | I25: Reuniones | J25: Silletería fija (fijada al piso) | K25: 3 | S25: F4
A26: Algeciras | B26: 41020 | C26: 0.3 | D26: 0.2 | E26: Alta | F26: 0.2 | G26: 0.08 | I26: Reuniones | J26: Silletería movil | K26: 5 | S26: Grupo de ocupación
A27: Almaguer | B27: 19022 | C27: 0.25 | D27: 0.25 | E27: Alta | F27: 0.16 | G27: 0.08 | I27: Reuniones | J27: Plataformas | K27: 5 | S27: 1 | T27: Grupo I: Estructuras de ocupación normal
A28: Almeida | B28: 15022 | C28: 0.25 | D28: 0.25 | E28: Alta | F28: 0.16 | G28: 0.08 | I28: Oficinas | J28: Corredores y escaleras | K28: 3 | S28: 1.1 | T28: Grupo II: Estructuras de ocupación especial
A29: Alpujarra | B29: 73024 | C29: 0.25 | D29: 0.25 | E29: Alta | F29: 0.14 | G29: 0.07 | I29: Oficinas | J29: Oficinas | K29: 2 | S29: 1.25 | T29: Grupo III: Edificaciones de atención a la comunidad
A30: Altamira | B30: 41026 | C30: 0.3 | D30: 0.15 | E30: Alta | F30: 0.2 | G30: 0.08 | I30: Oficinas | J30: Restaurantes | K30: 5 | S30: 1.5 | T30: Grupo IV: Edificaciones indispensables
A31: Alto Baudó | B31: 27025 | C31: 0.4 | D31: 0.4 | E31: Alta | F31: 0.24 | G31: 0.1 | I31: Educativos | J31: Salones de clase | K31: 2
A32: Altos del Rosario | B32: 13030 | C32: 0.15 | D32: 0.15 | E32: Intermedia | F32: 0.06 | G32: 0.03 | I32: Educativos | J32: Corredores y escaleras | K32: 5
A33: Alvarado | B33: 73026 | C33: 0.2 | D33: 0.2 | E33: Intermedia | F33: 0.13 | G33: 0.07 | I33: Educativos | J33: Bibliotecas - Salón lectura | K33: 2
A34: Amagá | B34: 5030 | C34: 0.15 | D34: 0.2 | E34: Alta | F34: 0.16 | G34: 0.09 | I34: Educativos | J34: Bibliotecas - Estanterias | K34: 7
A35: Amalfi | B35: 5031 | C35: 0.15 | D35: 0.2 | E35: Intermedia | F35: 0.07 | G35: 0.04 | I35: Residencial | J35: Balcones | K35: 5
A36: Ambalema | B36: 73030 | C36: 0.2 | D36: 0.2 | E36: Intermedia | F36: 0.1 | G36: 0.06 | I36: Residencial | J36: Cuartos privados y sus corredores | K36: 1.8
A37: Anapóima | B37: 25035 | C37: 0.15 | D37: 0.2 | E37: Intermedia | F37: 0.13 | G37: 0.06 | I37: Residencial | J37: Escaleras | K37: 3
A38: Ancuyá | B38: 52036 | C38: 0.25 | D38: 0.25 | E38: Alta | F38: 0.15 | G38: 0.08 | I38: Almacenamiento | J38: Livianos | K38: 6
A39: Andalucía | B39: 76036 | C39: 0.25 | D39: 0.25 | E39: Alta | F39: 0.14 | G39: 0.09 | I39: Almacenamiento | J39: Pesado | K39: 12
A40: Andes | B40: 5034 | C40: 0.25 | D40: 0.3 | E40: Alta | F40: 0.17 | G40: 0.1 | I40: Garajes | J40: Garajes para automoviles de pasajeros | K40: 2.5
...

Sheet ESPECTRO NSR-10
A1: T (seg) | B1: Sa
A2: 0 | B2: =IF(A2<=$E$33,2.5*$E$21*$E$27*$H$15,IF(AND(A2>$E$33,A2<=$E$34),1.2*$E$24*$E$30*$H$15/A2,1.2*$E$24*$E$30*$E$34*$H$15/(A2^2))) -> 0.9 | D2: Ubicación: | F2: Número de pisos: | H2: Altura edificio (m):
A3: =+A2+0.025 -> 0.025 | B3: =IF(A3<=$E$33,2.5*$E$21*$E$27*$H$15,IF(AND(A3>$E$33,A3<=$E$34),1.2*$E$24*$E$30*$H$15/A3,1.2*$E$24*$E$30*$E$34*$H$15/(A3^2))) -> 0.9 | D3: Pereira | F3: 16 | H3: 37.8
A4: =+A3+0.025 -> 0.05 | B4: =IF(A4<=$E$33,2.5*$E$21*$E$27*$H$15,IF(AND(A4>$E$33,A4<=$E$34),1.2*$E$24*$E$30*$H$15/A4,1.2*$E$24*$E$30*$E$34*$H$15/(A4^2))) -> 0.9
A5: =+A4+0.025 -> 0.075 | B5: =IF(A5<=$E$33,2.5*$E$21*$E$27*$H$15,IF(AND(A5>$E$33,A5<=$E$34),1.2*$E$24*$E$30*$H$15/A5,1.2*$E$24*$E$30*$E$34*$H$15/(A5^2))) -> 0.9 | D5: Sistema estructural:
A6: =+A5+0.025 -> 0.1 | B6: =IF(A6<=$E$33,2.5*$E$21*$E$27*$H$15,IF(AND(A6>$E$33,A6<=$E$34),1.2*$E$24*$E$30*$H$15/A6,1.2*$E$24*$E$30*$E$34*$H$15/(A6^2))) -> 0.9 | D6: 4. Sistema estructural basado en muros de rigidez
A7: =+A6+0.025 -> 0.125 | B7: =IF(A7<=$E$33,2.5*$E$21*$E$27*$H$15,IF(AND(A7>$E$33,A7<=$E$34),1.2*$E$24*$E$30*$H$15/A7,1.2*$E$24*$E$30*$E$34*$H$15/(A7^2))) -> 0.9 | I7: Ro
A8: =+A7+0.025 -> 0.15 | B8: =IF(A8<=$E$33,2.5*$E$21*$E$27*$H$15,IF(AND(A8>$E$33,A8<=$E$34),1.2*$E$24*$E$30*$H$15/A8,1.2*$E$24*$E$30*$E$34*$H$15/(A8^2))) -> 0.9 | D8: Sistema estructural (tablas A.3-1:3 de la NSR-10) | I8: =+VLOOKUP(D9,TABLAS!N9:P17,2,FALSE) -> 5
A9: =+A8+0.025 -> 0.175 | B9: =IF(A9<=$E$33,2.5*$E$21*$E$27*$H$15,IF(AND(A9>$E$33,A9<=$E$34),1.2*$E$24*$E$30*$H$15/A9,1.2*$E$24*$E$30*$E$34*$H$15/(A9^2))) -> 0.9 | D9: Muros estructurales de concreto (DES)
A10: =+A9+0.025 -> 0.2 | B10: =IF(A10<=$E$33,2.5*$E$21*$E$27*$H$15,IF(AND(A10>$E$33,A10<=$E$34),1.2*$E$24*$E$30*$H$15/A10,1.2*$E$24*$E$30*$E$34*$H$15/(A10^2))) -> 0.9 | I10: Ωo
A11: =+A10+0.025 -> 0.225 | B11: =IF(A11<=$E$33,2.5*$E$21*$E$27*$H$15,IF(AND(A11>$E$33,A11<=$E$34),1.2*$E$24*$E$30*$H$15/A11,1.2*$E$24*$E$30*$E$34*$H$15/(A11^2))) -> 0.9 | D11: Tipo de perfil de suelo (tabla A.2.4-1 de la NSR-10 ): | I11: =+VLOOKUP(D9,TABLAS!N9:P17,3,FALSE) -> 2.5
A12: =+A11+0.025 -> 0.25 | B12: =IF(A12<=$E$33,2.5*$E$21*$E$27*$H$15,IF(AND(A12>$E$33,A12<=$E$34),1.2*$E$24*$E$30*$H$15/A12,1.2*$E$24*$E$30*$E$34*$H$15/(A12^2))) -> 0.9 | D12: D | E12: Zona 3
A13: =+A12+0.025 -> 0.275 | B13: =IF(A13<=$E$33,2.5*$E$21*$E$27*$H$15,IF(AND(A13>$E$33,A13<=$E$34),1.2*$E$24*$E$30*$H$15/A13,1.2*$E$24*$E$30*$E$34*$H$15/(A13^2))) -> 0.9
A14: =+A13+0.025 -> 0.3 | B14: =IF(A14<=$E$33,2.5*$E$21*$E$27*$H$15,IF(AND(A14>$E$33,A14<=$E$34),1.2*$E$24*$E$30*$H$15/A14,1.2*$E$24*$E$30*$E$34*$H$15/(A14^2))) -> 0.9 | D14: Factor de importancia
A15: =+A14+0.025 -> 0.325 | B15: =IF(A15<=$E$33,2.5*$E$21*$E$27*$H$15,IF(AND(A15>$E$33,A15<=$E$34),1.2*$E$24*$E$30*$H$15/A15,1.2*$E$24*$E$30*$E$34*$H$15/(A15^2))) -> 0.9 | D15: Grupo I: Estructuras de ocupación normal | H15: =+INDEX(TABLAS!$S$27:$S$30,MATCH($D$15,TABLAS!$T$27:$T$30,0),1) -> 1 | I15: (NSR-10 A.2.5)
A16: =+A15+0.025 -> 0.35 | B16: =IF(A16<=$E$33,2.5*$E$21*$E$27*$H$15,IF(AND(A16>$E$33,A16<=$E$34),1.2*$E$24*$E$30*$H$15/A16,1.2*$E$24*$E$30*$E$34*$H$15/(A16^2))) -> 0.9
A17: =+A16+0.025 -> 0.375 | B17: =IF(A17<=$E$33,2.5*$E$21*$E$27*$H$15,IF(AND(A17>$E$33,A17<=$E$34),1.2*$E$24*$E$30*$H$15/A17,1.2*$E$24*$E$30*$E$34*$H$15/(A17^2))) -> 0.9 | D17: Nivel de amenaza sísmica:
A18: =+A17+0.025 -> 0.4 | B18: =IF(A18<=$E$33,2.5*$E$21*$E$27*$H$15,IF(AND(A18>$E$33,A18<=$E$34),1.2*$E$24*$E$30*$H$15/A18,1.2*$E$24*$E$30*$E$34*$H$15/(A18^2))) -> 0.9 | D18: =VLOOKUP(D3,TABLAS!A2:G1124,5,FALSE) -> Alta
A19: =+A18+0.025 -> 0.425 | B19: =IF(A19<=$E$33,2.5*$E$21*$E$27*$H$15,IF(AND(A19>$E$33,A19<=$E$34),1.2*$E$24*$E$30*$H$15/A19,1.2*$E$24*$E$30*$E$34*$H$15/(A19^2))) -> 0.9
A20: =+A19+0.025 -> 0.45 | B20: =IF(A20<=$E$33,2.5*$E$21*$E$27*$H$15,IF(AND(A20>$E$33,A20<=$E$34),1.2*$E$24*$E$30*$H$15/A20,1.2*$E$24*$E$30*$E$34*$H$15/(A20^2))) -> 0.9 | D20: Coeficiente de aceleración horizontal pico efectiva
A21: =+A20+0.025 -> 0.475 | B21: =IF(A21<=$E$33,2.5*$E$21*$E$27*$H$15,IF(AND(A21>$E$33,A21<=$E$34),1.2*$E$24*$E$30*$H$15/A21,1.2*$E$24*$E$30*$E$34*$H$15/(A21^2))) -> 0.9 | D21: Aa = | E21: =VLOOKUP(D3,TABLAS!A2:G1124,3,FALSE) -> 0.25
A22: =+A21+0.025 -> 0.5 | B22: =IF(A22<=$E$33,2.5*$E$21*$E$27*$H$15,IF(AND(A22>$E$33,A22<=$E$34),1.2*$E$24*$E$30*$H$15/A22,1.2*$E$24*$E$30*$E$34*$H$15/(A22^2))) -> 0.9
A23: =+A22+0.025 -> 0.525 | B23: =IF(A23<=$E$33,2.5*$E$21*$E$27*$H$15,IF(AND(A23>$E$33,A23<=$E$34),1.2*$E$24*$E$30*$H$15/A23,1.2*$E$24*$E$30*$E$34*$H$15/(A23^2))) -> 0.9 | D23: Coeficiente de velocidad horizontal pico efectiva
A24: =+A23+0.025 -> 0.55 | B24: =IF(A24<=$E$33,2.5*$E$21*$E$27*$H$15,IF(AND(A24>$E$33,A24<=$E$34),1.2*$E$24*$E$30*$H$15/A24,1.2*$E$24*$E$30*$E$34*$H$15/(A24^2))) -> 0.9 | D24: Av = | E24: =VLOOKUP(D3,TABLAS!A2:G1124,4,FALSE) -> 0.25
A25: =+A24+0.025 -> 0.575 | B25: =IF(A25<=$E$33,2.5*$E$21*$E$27*$H$15,IF(AND(A25>$E$33,A25<=$E$34),1.2*$E$24*$E$30*$H$15/A25,1.2*$E$24*$E$30*$E$34*$H$15/(A25^2))) -> 0.9
A26: =+A25+0.025 -> 0.6 | B26: =IF(A26<=$E$33,2.5*$E$21*$E$27*$H$15,IF(AND(A26>$E$33,A26<=$E$34),1.2*$E$24*$E$30*$H$15/A26,1.2*$E$24*$E$30*$E$34*$H$15/(A26^2))) -> 0.9 | D26: Coeficiente de amplificación que afecta la aceleración en la zona de períodos cortos
A27: =+A26+0.025 -> 0.625 | B27: =IF(A27<=$E$33,2.5*$E$21*$E$27*$H$15,IF(AND(A27>$E$33,A27<=$E$34),1.2*$E$24*$E$30*$H$15/A27,1.2*$E$24*$E$30*$E$34*$H$15/(A27^2))) -> 0.9 | D27: Fa= | E27: 1.44 | F27: Microzonificación sismica
A28: =+A27+0.025 -> 0.65 | B28: =IF(A28<=$E$33,2.5*$E$21*$E$27*$H$15,IF(AND(A28>$E$33,A28<=$E$34),1.2*$E$24*$E$30*$H$15/A28,1.2*$E$24*$E$30*$E$34*$H$15/(A28^2))) -> 0.9
A29: =+A28+0.025 -> 0.675 | B29: =IF(A29<=$E$33,2.5*$E$21*$E$27*$H$15,IF(AND(A29>$E$33,A29<=$E$34),1.2*$E$24*$E$30*$H$15/A29,1.2*$E$24*$E$30*$E$34*$H$15/(A29^2))) -> 0.9 | D29: Coeficiente de amplificación que afecta la aceleración en la zona de períodos intermedios.
A30: =+A29+0.025 -> 0.7 | B30: =IF(A30<=$E$33,2.5*$E$21*$E$27*$H$15,IF(AND(A30>$E$33,A30<=$E$34),1.2*$E$24*$E$30*$H$15/A30,1.2*$E$24*$E$30*$E$34*$H$15/(A30^2))) -> 0.9 | D30: Fv= | E30: 2.4 | F30: Microzonificación sismica
A31: =+A30+0.025 -> 0.725 | B31: =IF(A31<=$E$33,2.5*$E$21*$E$27*$H$15,IF(AND(A31>$E$33,A31<=$E$34),1.2*$E$24*$E$30*$H$15/A31,1.2*$E$24*$E$30*$E$34*$H$15/(A31^2))) -> 0.9
A32: =+A31+0.025 -> 0.75 | B32: =IF(A32<=$E$33,2.5*$E$21*$E$27*$H$15,IF(AND(A32>$E$33,A32<=$E$34),1.2*$E$24*$E$30*$H$15/A32,1.2*$E$24*$E$30*$E$34*$H$15/(A32^2))) -> 0.9 | D32: · TO = | E32: =0.1*(E24*E30)/(E21*E27) -> 0.16666667
A33: =+A32+0.025 -> 0.775 | B33: =IF(A33<=$E$33,2.5*$E$21*$E$27*$H$15,IF(AND(A33>$E$33,A33<=$E$34),1.2*$E$24*$E$30*$H$15/A33,1.2*$E$24*$E$30*$E$34*$H$15/(A33^2))) -> 0.9 | D33: · Tc = | E33: =0.48*(E24*E30)/(E21*E27) -> 0.8
A34: =+A33+0.025 -> 0.8 | B34: =IF(A34<=$E$33,2.5*$E$21*$E$27*$H$15,IF(AND(A34>$E$33,A34<=$E$34),1.2*$E$24*$E$30*$H$15/A34,1.2*$E$24*$E$30*$E$34*$H$15/(A34^2))) -> 0.9 | D34: · TL = | E34: =2.4*E30 -> 5.76
A35: =+A34+0.025 -> 0.825 | B35: =IF(A35<=$E$33,2.5*$E$21*$E$27*$H$15,IF(AND(A35>$E$33,A35<=$E$34),1.2*$E$24*$E$30*$H$15/A35,1.2*$E$24*$E$30*$E$34*$H$15/(A35^2))) -> 0.87272727
A36: =+A35+0.025 -> 0.85 | B36: =IF(A36<=$E$33,2.5*$E$21*$E$27*$H$15,IF(AND(A36>$E$33,A36<=$E$34),1.2*$E$24*$E$30*$H$15/A36,1.2*$E$24*$E$30*$E$34*$H$15/(A36^2))) -> 0.84705882 | D36: Donde,
A37: =+A36+0.025 -> 0.875 | B37: =IF(A37<=$E$33,2.5*$E$21*$E$27*$H$15,IF(AND(A37>$E$33,A37<=$E$34),1.2*$E$24*$E$30*$H$15/A37,1.2*$E$24*$E$30*$E$34*$H$15/(A37^2))) -> 0.82285714
A38: =+A37+0.025 -> 0.9 | B38: =IF(A38<=$E$33,2.5*$E$21*$E$27*$H$15,IF(AND(A38>$E$33,A38<=$E$34),1.2*$E$24*$E$30*$H$15/A38,1.2*$E$24*$E$30*$E$34*$H$15/(A38^2))) -> 0.8 | D38: T0 = Período de vibración, en segundos, correspondiente al inicio de la zona de desplazamiento
A39: =+A38+0.025 -> 0.925 | B39: =IF(A39<=$E$33,2.5*$E$21*$E$27*$H$15,IF(AND(A39>$E$33,A39<=$E$34),1.2*$E$24*$E$30*$H$15/A39,1.2*$E$24*$E$30*$E$34*$H$15/(A39^2))) -> 0.77837838 | D39: aproximadamente constante del espectro de diseño, para períodos largos. (NSR-10 A.2.6).
A40: =+A39+0.025 -> 0.95 | B40: =IF(A40<=$E$33,2.5*$E$21*$E$27*$H$15,IF(AND(A40>$E$33,A40<=$E$34),1.2*$E$24*$E$30*$H$15/A40,1.2*$E$24*$E$30*$E$34*$H$15/(A40^2))) -> 0.75789474 | D40: TC = Período de vibración, en segundos, correspondiente a la transición entre la zona de aceleración constante
...

Sheet Análisis de Cargas
B2: Carga Sobreimpuesta
B3: Zona | C3: Acabado | D3: Peso por m2 | E3: Total D_SP
B4: Cubierta | C4: Teja fibrocemento 14 mm | D4: 0.2 | E4: =+SUM(D4:D6) -> 0.55 | H4: U_B.2.4-5_1 DER_H
C5: Cieloraso | D5: 0.2 | H5: U_B.2.4-5_1 DER
C6: Correas | D6: 0.15 | H6: U_B.2.4-5_2 DER_H
C7: Espesor equivalente en concreto | D7: =+SUM(D4:D6)/24 -> 0.022916667 | H7: U_B.2.4-5_2 DER
B8: Auditorio | C8: Baldosa sobre mortero | D8: 1.1 | E8: =+SUM(D8:D9) -> 1.4 | H8: U_B.2.4-5_3 DER_H
C9: Cieloraso | D9: 0.3 | H9: U_B.2.4-5_3 DER
B10: C. Privados, Oficina y circulación | C10: Baldosa sobre mortero | D10: 1.1 | E10: =+SUM(D10:D11) -> 1.4 | H10: U_B.2.4-5_4 DER_H
C11: Cieloraso | D11: 0.3 | H11: U_B.2.4-5_4 DER
B12: Habitaciones | C12: Baldosa sobre mortero | D12: 0.8 | E12: =+SUM(D12:D13) -> 1.1 | H12: U_B.2.4-7_1 DER_H
C13: Cieloraso | D13: 0.3 | H13: U_B.2.4-7_1 DER
B14: Balcones y Terrazas | C14: Baldosa sobre mortero | D14: 1.1 | E14: =+SUM(D14:D15) -> 1.4 | H14: U_B.2.4-7_2 DER_H
C15: Cieloraso | D15: 0.3 | H15: U_B.2.4-7_2 DER
B16: Zona lavado | C16: Baldosa sobre mortero | D16: 1.1 | E16: =+SUM(D16:D17) -> 1.4 | H16: U_B.2.4-7_3 DER_H
C17: Cieloraso | D17: 0.3 | H17: U_B.2.4-7_3 DER
B18: Restaurante | C18: Baldosa sobre mortero | D18: 1.1 | E18: =+SUM(D18:D19) -> 1.4 | H18: U_B.2.4-7_4 DER_H
C19: Cieloraso | D19: 0.3 | H19: U_B.2.4-7_4 DER
B20: Almacenamiento | C20: Baldosa sobre mortero | D20: 1.1 | E20: =+SUM(D20:D21) -> 1.4
C21: Cieloraso | D21: 0.3
B22: Escalera | C22: Baldosa sobre mortero | D22: 1.1 | E22: =+SUM(D22:D22) -> 1.1
A26: ANÁLISIS ESTRUCTURAL SISMICO EDIFICIO INSTITUCIONAL - UNIESTATAL LA DORADA - CALDAS
A27: 1. PREDIMENSIONAMIENTO Y COORDINACIÓN CON LOS OTROS PROFESIONALES
A28: Definición del sistema estructural, dimensiones tentativas para evaluar preliminarmente las diferentes solicitaciones tales como: la masa de la
A29: estructura, las cargas muertas, las cargas vivas, los efectos sísmicos, y las fuerzas de viento. Estas dimensiones preliminares se coordinan
A30: con los otros profesionales que participan en el diseño.
A32: 2. EVALUACIÓN DE LAS SOLICITACIONES DEFINITIVAS
A33: Con las dimensiones de los elementos de la estructura definidas como resultado del paso 1, se evalúan todas las solicitaciones que pueden
A34: afectar la edificación de acuerdo con los requisitos del Titulo B de la NSR-10. Estas incluyen: el efecto gravitacional de la masa de los elementos
A35: estructurales, o peso propio, las cargas de acabados y elementos no estructurales, las cargas vivas, las fuerzas de viento, las deformaciones
A36: impuestas por las fuerzas de viento, las deformaciones impuestas por efectos reológicos de los materiales estructurales y asentamientos del
A37: suelo que da apoyo a la fundación. Así mismo se debe determinar la masa de la edificación y su contenido cuando así lo exige la NSR-10, la
A38: cual será empleada en la determinación de los efectos sísmicos.
... A44: Densidades de materiales
A45: gconc = | B45: 24 | C45: (Peso específico del concreto)
A46: gmamp = | B46: 16.5 | C46: (Peso específico de la mampostería)
A49: LOSA APARATAMENTOS PISO 1 AL 12
A50: W = | B50: 0.8 | C50: Baldosa ceramica+ 25mm de mortero
A51: TOTAL | B51: =SUM(B50:B50) -> 0.8
A53: Peso propio de losa
...

Sheet Análisis
A1: 3. OBTENCION DEL NIVEL DE AMENAZA SÍSMICA Y LOS VALORES DE Aa Y Av
A2: Se localiza el lugar donde se construirá la edificación dentro de los mapas de zonificación sísmica dados en el Capitulo A.2 de la NSR-10 y en
A3: determinar el nivel de amenaza sísmica del lugar, de acuerdo con los valores de los parámetros Aa y Av obtenidos en los mapas de zonificación
A4: sísmica del Capitulo A.2. El nivel de amenaza sísmica se clasificará como alta, intermedia o baja. En el Apéndice A-4 se presenta una
A5: enumeración de los municipios colombianos, con su definición de la zona de amenaza sísmica y los valores de los parámetros Aa y Av.
A7: Localización: | C7: =+'ESPECTRO NSR-10'!D3 -> Pereira
A8: Nivel de amenaza sísmica: | C8: =+'ESPECTRO NSR-10'!D18 -> Alta
A9: Coeficiente de aceleración | C9: Aa = | D9: =+'ESPECTRO NSR-10'!E21 -> 0.25 | E9: =+'ESPECTRO NSR-10'!D20 -> Coeficiente de aceleración horizontal pico efectiva
C10: Av = | D10: =+'ESPECTRO NSR-10'!E24 -> 0.25 | E10: =+'ESPECTRO NSR-10'!D23 -> Coeficiente de velocidad horizontal pico efectiva
A12: 4. MOVIMIENTOS SÍSMICOS DE DISEÑO
A13: Deben definirse unos movimientos sísmicos de diseño en el lugar de la edificación, de acuerdo con los requisitos del Capitulo A.2 de la NSR-10
A14: y, en el caso de Edificaciones cubiertas por A.1.2.3.3 (Grupo III y IV), con los requisitos del Capitulo A.12 de la NSR-10, tomando en cuenta:
A15: (a) La amenaza sísmica para el lugar determinada en el punto 3, expresada a través de Aa y Av, o Ad, según aplique.
A16: (b) Las caracterisiticas de estratificacion del suelo subyacente en el lugar a traves de Fa y Fv.
A17: (c ) La imporancia de la edificacion para la recuperacion de la comunidad con posterioridad a la ocurrencia de un sismo a través de I.
A18: Las caracteristicas de los movimientos sismicos de diseño se expresan por medio de un espectro elastico de diseño, una familia de
A19: acelerogramas o resultados de una microzonificacion sismica.
A21: =+'ESPECTRO NSR-10'!D11 -> Tipo de perfil de suelo (tabla A.2.4-1 de la NSR-10 ): | G21: =+'ESPECTRO NSR-10'!D12 -> D
A22: =+'ESPECTRO NSR-10'!D26 -> Coeficiente de amplificación que afecta la aceleración en la zona de períodos cortos | G22: =+'ESPECTRO NSR-10'!D27 -> Fa= | H22: =+'ESPECTRO NSR-10'!E27 -> 1.44
A23: =+'ESPECTRO NSR-10'!D29 -> Coeficiente de amplificación que afecta la aceleración en la zona de períodos intermedios. | G23: =+'ESPECTRO NSR-10'!D30 -> Fv= | H23: =+'ESPECTRO NSR-10'!E30 -> 2.4
A24: =+'ESPECTRO NSR-10'!D14 -> Factor de importancia | C24: ='ESPECTRO NSR-10'!$D$15 -> Grupo I: Estructuras de ocupación normal | G24: =+'ESPECTRO NSR-10'!H15 -> 1
A25: Movimientos sísmicos de diseño: | C25: Expresados como el espectro elástico de diseño de la NSR-10.
A27: De acuerdo con la seccion A.2.6 de la NSR-10, se define el espectro elastico de aceleraciones, con Sa expresada como
A28: fracción de la gravedad, para un coeficiente de 5% del amortiguamiento critico.
A43: Espectro elástico de diseño de la NSR-10.
A45: Factor de importancia
A46: ='ESPECTRO NSR-10'!D15 -> Grupo I: Estructuras de ocupación normal | E46: ='ESPECTRO NSR-10'!H15 -> 1 | F46: ='ESPECTRO NSR-10'!I15 -> (NSR-10 A.2.5)
A48: Coeficiente de aceleración horizontal pico efectiva:
A49: ='ESPECTRO NSR-10'!D21 -> Aa = | B49: ='ESPECTRO NSR-10'!E21 -> 0.25
A51: Coeficiente de velocidad horizontal pico efectiva:
A52: ='ESPECTRO NSR-10'!D24 -> Av = | B52: ='ESPECTRO NSR-10'!E24 -> 0.25
A54: =+'ESPECTRO NSR-10'!D11 -> Tipo de perfil de suelo (tabla A.2.4-1 de la NSR-10 ):
A55: =+'ESPECTRO NSR-10'!D12 -> D
A57: Coeficiente de amplificación que afecta la aceleración en la zona de períodos cortos
A58: Fa= | B58: =+'ESPECTRO NSR-10'!E27 -> 1.44
A60: Coeficiente de amplificación que afecta la aceleración en la zona de períodos intermedios
A61: Fv= | B61: =+'ESPECTRO NSR-10'!E30 -> 2.4
A63: · TO = | B63: =+'ESPECTRO NSR-10'!E32 -> 0.16666667
A64: · Tc = | B64: =+'ESPECTRO NSR-10'!E33 -> 0.8
A65: · TL = | B65: =+'ESPECTRO NSR-10'!E34 -> 5.76
...
